Workbook

Sheet サマリー
A1: AI映像制作事業 5年計画サマリー（Ver0.7）
A2: 単位：百万円。事業×商品まで割って積み上げたもの。一本値は使っていない。⚠［仮置き］の前提に乗った計画であり、実績ではない。
A3: 項目 | C3: 1期 | D3: 2期 | E3: 3期 | F3: 4期 | G3: 5期 | H3: 備考
A4: 売上高 | C4: ='損益計算書'!C12 | D4: ='損益計算書'!D12 | E4: ='損益計算書'!E12 | F4: ='損益計算書'!F12 | G4: ='損益計算書'!G12
A5: ① 映像制作 | C5: ='損益計算書'!C4 | D5: ='損益計算書'!D4 | E5: ='損益計算書'!E4 | F5: ='損益計算書'!F4 | G5: ='損益計算書'!G4 | H5: 4商品・本数は営業体制から
A6: ② ツール外販 | C6: ='損益計算書'!C10 | D6: ='損益計算書'!D10 | E6: ='損益計算書'!E10 | F6: ='損益計算書'!F10 | G6: ='損益計算書'!G10 | H6: 法人2階建て＋個人＋セルフサーブ
A7: ③ 越境C2C手数料 | C7: ='損益計算書'!C11 | D7: ='損益計算書'!D11 | E7: ='損益計算書'!E11 | F7: ='損益計算書'!F11 | G7: ='損益計算書'!G11 | H7: 14商品・手数料30%
A8: 売上総利益 | C8: ='損益計算書'!C18 | D8: ='損益計算書'!D18 | E8: ='損益計算書'!E18 | F8: ='損益計算書'!F18 | G8: ='損益計算書'!G18
A9: 営業利益 | C9: ='損益計算書'!C29 | D9: ='損益計算書'!D29 | E9: ='損益計算書'!E29 | F9: ='損益計算書'!F29 | G9: ='損益計算書'!G29
A10: 営業利益率 | C10: ='損益計算書'!C30 | D10: ='損益計算書'!D30 | E10: ='損益計算書'!E30 | F10: ='損益計算書'!F30 | G10: ='損益計算書'!G30
A11: 営業キャッシュフロー | C11: ='資金計画'!C14 | D11: ='資金計画'!D14 | E11: ='資金計画'!E14 | F11: ='資金計画'!F14 | G11: ='資金計画'!G14 | H11: 税・運転資本の後
A12: 期末キャッシュ残高 | C12: ='資金計画'!C22 | D12: ='資金計画'!D22 | E12: ='資金計画'!E22 | F12: ='資金計画'!F22 | G12: ='資金計画'!G22 | H12: 一度もマイナスにならないこと
A13: 社員数 | C13: ='損益計算書'!C33 | D13: ='損益計算書'!D33 | E13: ='損益計算書'!E33 | F13: ='損益計算書'!F33 | G13: ='損益計算書'!G33 | H13: 業務委託・BPOは含まない
A14: 売上 / 社員（万円） | C14: ='損益計算書'!C34 | D14: ='損益計算書'!D34 | E14: ='損益計算書'!E34 | F14: ='損益計算書'!F34 | G14: ='損益計算書'!G34
A15: 人手に比例しない収益 比率 | C15: ='損益計算書'!C37 | D15: ='損益計算書'!D37 | E15: ='損益計算書'!E37 | F15: ='損益計算書'!F37 | G15: ='損益計算書'!G37 | H15: 受託と読まれないための中心指標
A16: 研究開発費 ÷ 売上 | C16: ='損益計算書'!C35 | D16: ='損益計算書'!D35 | E16: ='損益計算書'!E35 | F16: ='損益計算書'!F35 | G16: ='損益計算書'!G35
A17: AX倍率 | C17: ='損益計算書'!C9 | D17: ='損益計算書'!D9 | E17: ='損益計算書'!E9 | F17: ='損益計算書'!F9 | G17: ='損益計算書'!G9 | H17: 最重要前提★。3倍でも成立する
A18: 顧客が浮かせる額 | C18: ='損益計算書'!C38 | D18: ='損益計算書'!D38 | E18: ='損益計算書'!E38 | F18: ='損益計算書'!F38 | G18: ='損益計算書'!G38 | H18: ①の提案の中身
A20: 継続収益（ARR）と非継続の内訳
A21: 項目 | C21: 1期 | D21: 2期 | E21: 3期 | F21: 4期 | G21: 5期 | H21: 考え方
A22: ① 映像制作 ARR | C22: ='商品マスタ①'!I21 | D22: ='商品マスタ①'!J21 | E22: ='商品マスタ①'!K21 | F22: ='商品マスタ①'!L21 | G22: ='商品マスタ①'!M21 | H22: 案件ベース。リテイナー契約分のみ（いまは0）
A23: ② ツール外販 ARR | C23: ='商品マスタ②'!C45 | D23: ='商品マスタ②'!D45 | E23: ='商品マスタ②'!E45 | F23: ='商品マスタ②'!F45 | G23: ='商品マスタ②'!G45 | H23: LoRA個別構築とセルフサーブ都度分を除く
A24: ③ 越境C2C ARR | C24: ='商品マスタ③'!C49 | D24: ='商品マスタ③'!D49 | E24: ='商品マスタ③'!E49 | F24: ='商品マスタ③'!F49 | G24: ='商品マスタ③'!G49 | H24: 取引ベースなのでゼロ
A25: 全社 ARR | C25: =C22+C23+C24 | D25: =D22+D23+D24 | E25: =E22+E23+E24 | F25: =F22+F23+F24 | G25: =G22+G23+G24 | H25: 投資家に「御社のARRは？」と聞かれたらこの行
A26: ARR比率（対 売上） | C26: =IF(C4=0,0,C25/C4) | D26: =IF(D4=0,0,D25/D4) | E26: =IF(E4=0,0,E25/E4) | F26: =IF(F4=0,0,F25/F4) | G26: =IF(G4=0,0,G25/G4) | H26: ②以外は継続収益にならない
A27: ⚠ 継続収益になるのは②だけ。①は案件ベース、③は取引ベース。下のライン別評価でツール6〜8倍・C2C4〜6倍・制作1.5〜2.5倍と差をつけているのは、まさにこの違いを反映している。
A29: シード投資家（1.42億）のリターン
A30: ケース | C30: 時価総額(億) | D30: 取り分(億) | E30: 倍率 | F30: IRR | H30: 根拠
A31: ライン別・保守 | C31: ='資本政策とリターン'!E13 | D31: ='資本政策とリターン'!F13 | E31: ='資本政策とリターン'!G13 | F31: ='資本政策とリターン'!H13 | H31: ツール6倍＋C2C4倍＋制作1.5倍
A32: ライン別・中庸 | C32: ='資本政策とリターン'!E14 | D32: ='資本政策とリターン'!F14 | E32: ='資本政策とリターン'!G14 | F32: ='資本政策とリターン'!H14 | H32: ツール7倍＋C2C5倍＋制作2.0倍
A33: ライン別・強気 | C33: ='資本政策とリターン'!E15 | D33: ='資本政策とリターン'!F15 | E33: ='資本政策とリターン'!G15 | F33: ='資本政策とリターン'!H15 | H33: ツール8倍＋C2C6倍＋制作2.5倍
A34: 全社 PSR 4倍 | C34: ='資本政策とリターン'!E19 | D34: ='資本政策とリターン'!F19 | E34: ='資本政策とリターン'!G19 | F34: ='資本政策とリターン'!H19 | H34: 人手に比例しない収益が9割であること
A35: 全社 PSR 5倍 | C35: ='資本政策とリターン'!E20 | D35: ='資本政策とリターン'!F20 | E35: ='資本政策とリターン'!G20 | F35: ='資本政策とリターン'!H20
A37: ⚠ 上の倍率は事業計画からの逆算であって、投資の推奨でも利回りの保証でもない。前提の多くは未実証（「出所と仮置き」シート参照）。
A39: このモデルの読み方
A40: 入力は「前提」と3つの「商品マスタ」の黄色セルだけ。ほかは全部そこを参照する数式。
A41: ①の平均単価と平均難度は、商品構成比から導出される。直接は入力できない。
A42: ③は成約が価格帯のどこに落ちるかで3倍動く。いまは中点（均等）を採用している。
A43: ⚠ xlsx を手で編集しないこと。make_xlsx15.py を直して再生成する。

Sheet 前提
A1: 前提（全社共通の入力）
A2: 黄色が入力。商品ごとの単価・件数は各「商品マスタ」シートにある。区分［仮置き］は未実証。
A3: 大分類 | B3: 項目 | C3: 1期 | D3: 2期 | E3: 3期 | F3: 4期 | G3: 5期 | H3: 単位 | I3: 区分 | J3: 備考・出所
A4: 制作 | B4: AX倍率 | C4: 1 | D4: 1.5 | E4: 2.2 | F4: 3 | G4: 4 | H4: 倍 | I4: ［仮置き］ | J4: 1人あたり制作本数の倍率。計画の最重要前提
B5: 中国クリエイターへの支払 | C5: 12 | D5: 12 | E5: 12 | F5: 12 | G5: 12 | H5: 万円/本 | I5: ［仮置き］ | J5: 難度1.0のとき。実効時給3,000〜6,000円で、③より厚く払う（松田さん決定）
B6: 制作ディレクション（AX前） | C6: 20 | D6: 20 | E6: 20 | F6: 20 | G6: 20 | H6: 万円/本 | I6: ［仮置き］ | J6: 業務委託。成果物単位なのでAX倍率で除される
B7: AIツール・素材・レンダリング | C7: 2 | D7: 2 | E7: 2 | F7: 2 | G7: 2 | H7: 万円/本 | I7: ［仮置き］ | J7: クラウドGPU・素材
B8: 品質バッファ（作り直し） | C8: 1.5 | D8: 1.5 | E8: 1.5 | F8: 1.5 | G8: 1.5 | H8: 万円/本 | I8: ［仮置き］ | J8: 検収落ちの引当
A9: 費用 | B9: 研究開発費 | C9: 30 | D9: 120 | E9: 450 | F9: 1000 | G9: 1600 | H9: 百万円 | I9: ［仮置き］ | J9: AX倍率を上げ続けるための投資
B10: BPO（CS・運用） | C10: 0 | D10: 10 | E10: 120 | F10: 450 | G10: 1000 | H10: 百万円 | I10: ［仮置き］ | J10: 社員ではなく外部委託
B11: 獲得費（固定分） | C11: 6 | D11: 40 | E11: 90 | F11: 150 | G11: 200 | H11: 百万円 | I11: ［仮置き］ | J11: C2C発注者の獲得ほか
B12: 獲得費率（①売上比） | C12: 0.06 | D12: 0.06 | E12: 0.06 | F12: 0.06 | G12: 0.06 | H12: % | I12: ［仮置き］ | J12: SALES_COST.md
B13: 獲得費率（②売上比） | C13: 0.15 | D13: 0.15 | E13: 0.15 | F13: 0.15 | G13: 0.15 | H13: % | I13: ［仮置き］ | J13: 営業・CS
B14: 代理店経由の比率（①） | C14: 0 | D14: 0.053 | E14: 0.099 | F14: 0.147 | G14: 0.159 | H14: % | I14: 計算値 | J14: 営業体制シートの代理店チャネル ÷ 総本数
B15: 代理店手数料率 | C15: 0.15 | D15: 0.15 | E15: 0.15 | F15: 0.15 | G15: 0.15 | H15: % | I15: ［仮置き］ | J15: ①の代理店チャネルに対して
B16: その他販管費率（売上比） | C16: 0.04 | D16: 0.04 | E16: 0.04 | F16: 0.04 | G16: 0.04 | H16: % | I16: ［仮置き］ | J16: オフィス・SaaS・法務
B17: 法定福利費等の負担率 | C17: 1.16 | D17: 1.16 | E17: 1.16 | F17: 1.16 | G17: 1.16 | H17: 倍 | I17: ［仮置き］ | J17: 年収に対する会社負担
A18: 資金 | B18: 実効税率 | C18: 0.3 | D18: 0.3 | E18: 0.3 | F18: 0.3 | G18: 0.3 | H18: % | I18: ［仮置き］ | J18: 繰越欠損金の控除後
B19: 売上債権 回転日数（①） | C19: 60 | D19: 60 | E19: 60 | F19: 60 | G19: 60 | H19: 日 | I19: ［仮置き］ | J19: 検収後の入金サイト
B20: 仕入債務 回転日数（①原価） | C20: 30 | D20: 30 | E20: 30 | F20: 30 | G20: 30 | H20: 日 | I20: ［仮置き］ | J20: 制作パートナーへの支払
B21: ツール外販の前受期間 | C21: 180 | D21: 180 | E21: 180 | F21: 180 | G21: 180 | H21: 日 | I21: ［仮置き］ | J21: 年額一括前受の平均残高
B22: 設備投資 | C22: 0 | D22: 0 | E22: 0 | F22: 0 | G22: 0 | H22: 百万円 | I22: 方針 | J22: クラウド前提。自社設備を持たない
B23: 調達：シード | C23: 150 | D23: 0 | E23: 0 | F23: 0 | G23: 0 | H23: 百万円 | I23: 確定 | J23: J-KISS 1.42億＋代表個人0.08億
B24: 調達：シリーズA | C24: 0 | D24: 300 | E24: 0 | F24: 0 | G24: 0 | H24: 百万円 | I24: 計画 | J24: 2期。無いと2期末に資金ショート
B25: 調達：借入 | C25: 0 | D25: 0 | E25: 0 | F25: 0 | G25: 0 | H25: 百万円 | I25: 方針 | J25: 借入はしない

Sheet クリエイター経済
A1: クリエイターがいくらなら受けるか — ③の価格下限はここから出る
A2: マーケットプレイスは供給側が受けなければ成立しない。拘束条件はクリエイター側にある。
A3: 項目 | B3: 値 | C3: 単位 | D3: 区分 | E3: 出所・考え方
A4: 中国 剪辑師 平均月給 | B4: 8935 | C4: 元/月 | D4: 実測 | E4: Indeed 中国（剪辑師の平均薪資）
A5: 為替 | B5: 21 | C5: 円/元 | D5: ［仮置き］ | E5: 2026年の水準
A6: 月あたり労働時間 | B6: 168 | C6: 時間 | D6: 前提 | E6: 21日 × 8時間
A7: 時給（雇用ベース） | B7: =B4*B5/B6 | C7: 円 | D7: 計算 | E7: ＝ 月給 × 為替 ÷ 労働時間
A8: フリーランス割増 | B8: 1.4 | C8: 倍 | D8: ［仮置き］ | E8: 社保なし・不安定・営業時間が無給の補償
A9: 受注の判断ライン | B9: =B7*B8 | C9: 円/時 | D9: 計算 | E9: これを下回ると誰も受けない
A10: 設計に使う時給（下限） | B10: 1600 | C10: 円/時 | D10: ★ | E10: 判断ラインに余裕を見た額。③の価格下限に使う
A11: 設計に使う時給（上限） | B11: 3500 | C11: 円/時 | D11: ★ | E11: 熟練クリエイター。月20,000元相当×割増
A13: 必要なクリエイター数 — ここが「なぜ中国か」の答え
A14: 項目 | B14: 値 | C14: 単位 | E14: 考え方
A15: ③ に必要な年間工数 | B15: ='商品マスタ③'!$I$23 | C15: 時間 | E15: 商品別の平均工数 × 件数
A16: ① に必要な年間工数 | B16: ='商品マスタ①'!$M$15*1000000/4000 | C16: 時間 | E16: クリエイター支払総額 ÷ 実効時給4,000円★
A17: フル稼働換算 | B17: =(B15+B16)/1800 | C17: 人 | E17: 1人あたり年1,800時間★
A18: 登録ベース（2〜3倍） | B18: =B17*2.5 | C18: 人 | E18: 全員が常時稼働はしない★
A19: 中国の母数（微短劇産業の直接就業者） | B19: 690000 | C19: 人 | E19: 中国網絡視聴協会 2024。上下流を含めた波及は203万人
A20: 必要人数 ÷ 母数 | B20: =B18/B19
A22: 同じ人数を日本で、時給1,600〜3,500円で受ける映像クリエイターとして千人規模集めるのは成立しない。「人が集まるか」が問題にならない場所を選んだ、という設計。これは制約ではなく中国とやる理由。

Sheet システム原価
A1: ③ のシステム原価を商品別に積む
A2: 以前ここは「120円/件」と置いていたが根拠がなかった。公表単価から積み直したもの。
A3: 項目 | B3: 値 | C3: 単位 | J3: 出所
A4: ストレージ | B4: 3.66 | C4: 円/GB/月 | J4: S3 Standard 東京（1TB/月 ≈ $25）
A5: 転送 | B5: 12.75 | C5: 円/GB | J5: CloudFront 東京（$0.085/GB・1ドル150円）
A6: 容量 | B6: 60 | C6: MB/分 | J6: ★1080p H.264 約8Mbps
A7: 保管期間 | B7: 3 | C7: ヶ月 | J7: ★検収後
A8: 版数 | B8: 3 | C8: 版 | J8: ★成果物＋中間版2本
A9: 転送倍率 | B9: 4 | C9: 倍 | J9: ★プレビュー＋ダウンロード
A10: AI-bot | B10: 40.5 | C10: 円/件 | J10: ★入力30,000＋出力12,000トークン。③-Cのみ
A11: アプリ基盤 | B11: 31.9 | C11: 円/件 | J11: ★月30万円 ÷ 年113,000件
A13: 商品別
A14: 商品 | B14: 尺(分) | C14: 容量MB | D14: ストレージ | E14: 転送 | F14: AI-bot | G14: 基盤 | H14: 合計 | I14: 5期件数
A15: SNS用ショート | B15: 0.5 | C15: =B15*$B$6 | D15: =C15/1024*$B$8*$B$7*$B$4 | E15: =C15/1024*$B$9*$B$5 | F15: 0 | G15: =$B$11 | H15: =SUM(D15:G15) | I15: 25000
A16: 誕生日ムービー | B16: 2 | C16: =B16*$B$6 | D16: =C16/1024*$B$8*$B$7*$B$4 | E16: =C16/1024*$B$9*$B$5 | F16: 0 | G16: =$B$11 | H16: =SUM(D16:G16) | I16: 12000
A17: 記念日ムービー | B17: 2.5 | C17: =B17*$B$6 | D17: =C17/1024*$B$8*$B$7*$B$4 | E17: =C17/1024*$B$9*$B$5 | F17: 0 | G17: =$B$11 | H17: =SUM(D17:G17) | I17: 8000
A18: イベント・余興ムービー | B18: 4 | C18: =B18*$B$6 | D18: =C18/1024*$B$8*$B$7*$B$4 | E18: =C18/1024*$B$9*$B$5 | F18: 0 | G18: =$B$11 | H18: =SUM(D18:G18) | I18: 10000
A19: WEBサイト用 | B19: 1.5 | C19: =B19*$B$6 | D19: =C19/1024*$B$8*$B$7*$B$4 | E19: =C19/1024*$B$9*$B$5 | F19: 0 | G19: =$B$11 | H19: =SUM(D19:G19) | I19: 6000
A20: ウェディングムービー | B20: 12 | C20: =B20*$B$6 | D20: =C20/1024*$B$8*$B$7*$B$4 | E20: =C20/1024*$B$9*$B$5 | F20: 0 | G20: =$B$11 | H20: =SUM(D20:G20) | I20: 9000
A21: 会社紹介ショート | B21: 2 | C21: =B21*$B$6 | D21: =C21/1024*$B$8*$B$7*$B$4 | E21: =C21/1024*$B$9*$B$5 | F21: 0 | G21: =$B$11 | H21: =SUM(D21:G21) | I21: 4000
A22: 採用（小規模・1職種） | B22: 3 | C22: =B22*$B$6 | D22: =C22/1024*$B$8*$B$7*$B$4 | E22: =C22/1024*$B$9*$B$5 | F22: 0 | G22: =$B$11 | H22: =SUM(D22:G22) | I22: 2500
A23: 商品・サービス紹介 | B23: 2 | C23: =B23*$B$6 | D23: =C23/1024*$B$8*$B$7*$B$4 | E23: =C23/1024*$B$9*$B$5 | F23: 0 | G23: =$B$11 | H23: =SUM(D23:G23) | I23: 5000
A24: 店舗・施設紹介 | B24: 1.5 | C24: =B24*$B$6 | D24: =C24/1024*$B$8*$B$7*$B$4 | E24: =C24/1024*$B$9*$B$5 | F24: 0 | G24: =$B$11 | H24: =SUM(D24:G24) | I24: 3500
A25: 展示会・イベント告知 | B25: 2 | C25: =B25*$B$6 | D25: =C25/1024*$B$8*$B$7*$B$4 | E25: =C25/1024*$B$9*$B$5 | F25: 0 | G25: =$B$11 | H25: =SUM(D25:G25) | I25: 2000
A26: SNS広告用（縦型3本） | B26: 1.5 | C26: =B26*$B$6 | D26: =C26/1024*$B$8*$B$7*$B$4 | E26: =C26/1024*$B$9*$B$5 | F26: 0 | G26: =$B$11 | H26: =SUM(D26:G26) | I26: 6000
A27: 個人オーダーメイド | B27: 3 | C27: =B27*$B$6 | D27: =C27/1024*$B$8*$B$7*$B$4 | E27: =C27/1024*$B$9*$B$5 | F27: =$B$10 | G27: =$B$11 | H27: =SUM(D27:G27) | I27: 8000
A28: 企業オーダーメイド | B28: 4 | C28: =B28*$B$6 | D28: =C28/1024*$B$8*$B$7*$B$4 | E28: =C28/1024*$B$9*$B$5 | F28: =$B$10 | G28: =$B$11 | H28: =SUM(D28:G28) | I28: 12000
A29: 加重平均（円/件） | H29: =SUMPRODUCT(H15:H28,I15:I28)/SUM(I15:I28)
A31: 尺が長いものほど重く、AI-botは③-Cだけに乗る。安い商品ほど手数料に占める割合が大きい。

Sheet 商品マスタ①
A1: ① 映像制作 — 商品別
A2: 当社価格は「企業の現行支払 × (1−値引率)」。顧客が浮かせる額がそのまま提案の中身になる。平均単価と平均難度は構成比から導出される。
A3: 商品 | B3: 現行支払 | C3: 値引率 | D3: 当社単価 | E3: 顧客削減 | F3: 難度 | G3: 原価@AX4 | H3: 粗利率 | I3: 構成比 1期 | J3: 構成比 2期 | K3: 構成比 3期 | L3: 構成比 4期 | M3: 構成比 5期 | N3: 主な販路
A4: ブランドムービー・Web CM | B4: 500 | C4: 0.5 | D4: =B4*(1-C4) | E4: =B4-D4 | F4: 3 | G4: =F4*('前提'!$G$5+'前提'!$G$6/'前提'!$G$4+'前提'!$G$7+'前提'!$G$8) | H4: =1-G4/D4 | I4: 0.04 | J4: 0.08 | K4: 0.12 | L4: 0.13 | M4: 0.15 | N4: 直販
A5: 企業VP・採用（ブランド型） | B5: 200 | C5: 0.5 | D5: =B5*(1-C5) | E5: =B5-D5 | F5: 1.8 | G5: =F5*('前提'!$G$5+'前提'!$G$6/'前提'!$G$4+'前提'!$G$7+'前提'!$G$8) | H5: =1-G5/D5 | I5: 0.25 | J5: 0.28 | K5: 0.31 | L5: 0.34 | M5: 0.35 | N5: 直販・代理店
A6: 企業VP・会社紹介（標準） | B6: 100 | C6: 0.5 | D6: =B6*(1-C6) | E6: =B6-D6 | F6: 1 | G6: =F6*('前提'!$G$5+'前提'!$G$6/'前提'!$G$4+'前提'!$G$7+'前提'!$G$8) | H6: =1-G6/D6 | I6: 0.46 | J6: 0.42 | K6: 0.38 | L6: 0.36 | M6: 0.35 | N6: 代理店・インバウンド
A7: 展示会・社内イベント映像 | B7: 60 | C7: 0.5 | D7: =B7*(1-C7) | E7: =B7-D7 | F7: 0.8 | G7: =F7*('前提'!$G$5+'前提'!$G$6/'前提'!$G$4+'前提'!$G$7+'前提'!$G$8) | H7: =1-G7/D7 | I7: 0.25 | J7: 0.22 | K7: 0.19 | L7: 0.17 | M7: 0.15 | N7: 制作会社経由
A8: 構成比 合計 | I8: =SUM(I4:I7) | J8: =SUM(J4:J7) | K8: =SUM(K4:K7) | L8: =SUM(L4:L7) | M8: =SUM(M4:M7)
A9: 平均単価（万円） | I9: =SUMPRODUCT($D$4:$D$7,I4:I7) | J9: =SUMPRODUCT($D$4:$D$7,J4:J7) | K9: =SUMPRODUCT($D$4:$D$7,K4:K7) | L9: =SUMPRODUCT($D$4:$D$7,L4:L7) | M9: =SUMPRODUCT($D$4:$D$7,M4:M7)
A10: 平均難度係数 | I10: =SUMPRODUCT($F$4:$F$7,I4:I7) | J10: =SUMPRODUCT($F$4:$F$7,J4:J7) | K10: =SUMPRODUCT($F$4:$F$7,K4:K7) | L10: =SUMPRODUCT($F$4:$F$7,L4:L7) | M10: =SUMPRODUCT($F$4:$F$7,M4:M7)
A11: 1本あたり原価（万円） | I11: =I10*('前提'!$C$5+'前提'!$C$6/'前提'!$C$4+'前提'!$C$7+'前提'!$C$8) | J11: =J10*('前提'!$D$5+'前提'!$D$6/'前提'!$D$4+'前提'!$D$7+'前提'!$D$8) | K11: =K10*('前提'!$E$5+'前提'!$E$6/'前提'!$E$4+'前提'!$E$7+'前提'!$E$8) | L11: =L10*('前提'!$F$5+'前提'!$F$6/'前提'!$F$4+'前提'!$F$7+'前提'!$F$8) | M11: =M10*('前提'!$G$5+'前提'!$G$6/'前提'!$G$4+'前提'!$G$7+'前提'!$G$8)
A12: 受注本数（営業体制シート） | I12: ='営業体制'!C$19 | J12: ='営業体制'!D$19 | K12: ='営業体制'!E$19 | L12: ='営業体制'!F$19 | M12: ='営業体制'!G$19
A13: ① 売上（百万円） | I13: =I12*I9/100 | J13: =J12*J9/100 | K13: =K12*K9/100 | L13: =L12*L9/100 | M13: =M12*M9/100
A14: 顧客が浮かせる額（百万円） | I14: =I12*SUMPRODUCT($E$4:$E$7,I4:I7)/100 | J14: =J12*SUMPRODUCT($E$4:$E$7,J4:J7)/100 | K14: =K12*SUMPRODUCT($E$4:$E$7,K4:K7)/100 | L14: =L12*SUMPRODUCT($E$4:$E$7,L4:L7)/100 | M14: =M12*SUMPRODUCT($E$4:$E$7,M4:M7)/100
A15: クリエイター支払総額（百万円） | I15: =I12*I10*'前提'!$C$5/100 | J15: =J12*J10*'前提'!$D$5/100 | K15: =K12*K10*'前提'!$E$5/100 | L15: =L12*L10*'前提'!$F$5/100 | M15: =M12*M10*'前提'!$G$5/100
A17: ACV / ARR — ①は案件ベースなので、そのままではARRにならない
A18: 項目 | I18: 1期 | J18: 2期 | K18: 3期 | L18: 4期 | M18: 5期 | N18: 考え方
A19: 取引アカウント数 | I19: ='営業体制'!C22 | J19: ='営業体制'!D22 | K19: ='営業体制'!E22 | L19: ='営業体制'!F22 | M19: ='営業体制'!G22 | N19: 営業体制シート
A20: アカウントあたり年間取引額（万円） | I20: =IF(I19=0,0,I13*100/I19) | J20: =IF(J19=0,0,J13*100/J19) | K20: =IF(K19=0,0,K13*100/K19) | L20: =IF(L19=0,0,L13*100/L19) | M20: =IF(M19=0,0,M13*100/M19) | N20: ACV相当。ただし契約ではなく案件の集まり
A21: ① ARR（百万円） | I21: =I13*$B$22 | J21: =J13*$B$22 | K21: =K13*$B$22 | L21: =L13*$B$22 | M21: =M13*$B$22 | N21: リテイナー契約分のみ。スポット受注はARRではない
A22: 年間リテイナー契約の比率 | B22: 0 | N22: ★「年◯本でいくら」の包括契約にした分だけARRに入る。いまは0
A23: ① 非継続（百万円） | I23: =I13-I21 | J23: =J13-J21 | K23: =K13-K21 | L23: =L13-L21 | M23: =M13-M21 | N23: 案件ごとの発注。毎年の継続は保証されない
A25: ①は1本ごとの発注で、翌年も同じ社が同じ本数を出す義務はない。だから「1社あたり年567万」はACV相当ではあってもARRではない。年間包括（リテイナー）契約を商品として作れば、その分はARRに算入できる。★要判断

Sheet 営業体制
A1: ① の受注本数を、営業体制から積む
A2: 市場シェアは結果であって計画の根拠にはならない。単位は「本」ではなく「アカウント」。企業は年に何本も出すので、取引社数 × 1社あたり本数で積む。
A3: 項目 | C3: 1期 | D3: 2期 | E3: 3期 | F3: 4期 | G3: 5期 | H3: 考え方
A4: 1 直販
A5: 事業開発（名） | C5: 1 | D5: 2 | E5: 4 | F5: 5 | G5: 6 | H5: 人員計画シートと同じ
A6: 1名あたり担当社数 | C6: 15 | D6: 25 | E6: 35 | F6: 40 | G6: 40 | H6: ★エンタープライズ営業の標準的な担当数
A7: 1社あたり年間本数 | C7: 4 | D7: 5 | E7: 6 | F7: 6 | G7: 6 | H7: ★採用・展示会・製品・IRで年6本
A8: 小計（本） | C8: =C5*C6*C7 | D8: =D5*D6*D7 | E8: =E5*E6*E7 | F8: =F5*F6*F7 | G8: =G5*G6*G7
A9: 2 制作会社経由
A10: ②の法人契約数 | C10: ='商品マスタ②'!C19 | D10: ='商品マスタ②'!D19 | E10: ='商品マスタ②'!E19 | F10: ='商品マスタ②'!F19 | G10: ='商品マスタ②'!G19 | H10: ②を売ることが①の営業になっている
A11: うち発注もする割合 | C11: 0 | D11: 0.2 | E11: 0.25 | F11: 0.3 | G11: 0.3 | H11: ★手に余る案件を当社に流す
A12: 1社あたり年間本数 | C12: 0 | D12: 6 | E12: 7 | F12: 8 | G12: 8 | H12: ★
A13: 小計（本） | C13: =ROUND(C10*C11*C12,0) | D13: =ROUND(D10*D11*D12,0) | E13: =ROUND(E10*E11*E12,0) | F13: =ROUND(F10*F11*F12,0) | G13: =ROUND(G10*G11*G12,0)
A14: 3 代理店経由
A15: 提携代理店数 | C15: 0 | D15: 2 | E15: 10 | F15: 25 | G15: 40 | H15: ★広告代理店・人材会社
A16: 1社あたり年間本数 | C16: 0 | D16: 8 | E16: 12 | F16: 15 | G16: 15 | H16: ★
A17: 小計（本） | C17: =C15*C16 | D17: =D15*D16 | E17: =E15*E16 | F17: =F15*F16 | G17: =G15*G16
A18: 4 インバウンド（本） | C18: 0 | D18: 20 | E18: 80 | F18: 200 | G18: 300 | H18: ★事例と検索から
A19: 受注本数 合計 | C19: =C8+C13+C17+C18 | D19: =D8+D13+D17+D18 | E19: =E8+E13+E17+E18 | F19: =F8+F13+F17+F18 | G19: =G8+G13+G17+G18
A21: 取引社数と1社あたり
A22: 取引アカウント数 | C22: =C5*C6+ROUND(C10*C11,0)+C15 | D22: =D5*D6+ROUND(D10*D11,0)+D15 | E22: =E5*E6+ROUND(E10*E11,0)+E15 | F22: =F5*F6+ROUND(F10*F11,0)+F15 | G22: =G5*G6+ROUND(G10*G11,0)+G15 | H22: 直販で持つのは一部だけ。残りはチャネル経由
A23: 1社あたり年間取引額（万円） | C23: =IF(C22=0,0,'商品マスタ①'!I13*100/C22) | D23: =IF(D22=0,0,'商品マスタ①'!J13*100/D22) | E23: =IF(E22=0,0,'商品マスタ①'!K13*100/E22) | F23: =IF(F22=0,0,'商品マスタ①'!L13*100/F22) | G23: =IF(G22=0,0,'商品マスタ①'!M13*100/G22)
A24: 直販が①売上に占める比率 | C24: =IF('商品マスタ①'!I13=0,0,C8*'商品マスタ①'!I9/100/'商品マスタ①'!I13) | D24: =IF('商品マスタ①'!J13=0,0,D8*'商品マスタ①'!J9/100/'商品マスタ①'!J13) | E24: =IF('商品マスタ①'!K13=0,0,E8*'商品マスタ①'!K9/100/'商品マスタ①'!K13) | F24: =IF('商品マスタ①'!L13=0,0,F8*'商品マスタ①'!L9/100/'商品マスタ①'!L13) | G24: =IF('商品マスタ①'!M13=0,0,G8*'商品マスタ①'!M9/100/'商品マスタ①'!M13) | H24: 営業人数に比例しない売り方になっているか

Sheet 商品マスタ②
A1: ② 制作ツール外販 — 商品別
A2: チェックポイントと工程ツールは別売り。LoRA個別構築は②の売上。法人は Enterprise / Standard の2階建て。★単価・席数・構成比は提案値。
A3: 商品 | B3: 課金形態 | C3: 単価(万円) | D3: 継続/一過性 | J3: 中身
A4: チェックポイント Enterprise | B4: 年額 | C4: 300 | D4: 継続 | J4: 全業種・商用利用
A5: チェックポイント Standard | B5: 年額 | C5: 100 | D5: 継続 | J5: 1業種
A6: 工程ツール（要件定義・自動チェック） | B6: 月額2万/席 | C6: 24 | D6: 継続 | J6: 1席あたり年額
A7: LoRA 年間保守 | B7: 年額 | C7: 24 | D7: 継続 | J7: 追加学習モデルの更新・再学習
A8: LoRA 個別構築 | B8: 初期・都度 | C8: 80 | D8: 一過性 | J8: 毎年は発生しない。ARRには入らない
A10: プラン構成
A11: プラン | B11: チェックポイント | C11: 工程ツール | D11: LoRA保守 | E11: 年額計 | F11: 席数
A12: Enterprise | B12: =C4 | C12: =C6*F12 | D12: =C7 | E12: =SUM(B12:D12) | F12: 10
A13: Standard | B13: =C5 | C13: =C6*F13 | D13: =C7 | E13: =SUM(B13:D13) | F13: 3
A15: LoRA個別構築の付帯率 | B15: 0.25 | C15: =C8*B15 | J15: 新規契約の25%が初年度に発注★
A17: 期別
A18: 項目 | C18: 1期 | D18: 2期 | E18: 3期 | F18: 4期 | G18: 5期 | J18: 考え方
A19: 法人契約数 | C19: 0 | D19: 15 | E19: 100 | F19: 320 | G19: 600 | J19: ★海外展開が前提
A20: Enterprise比率 | C20: 0 | D20: 0.13 | E20: 0.2 | F20: 0.25 | G20: 0.3 | J20: ★事例が増えるほど上位プランが取れる
A21: Enterprise 社数 | C21: =ROUND(C19*C20,0) | D21: =ROUND(D19*D20,0) | E21: =ROUND(E19*E20,0) | F21: =ROUND(F19*F20,0) | G21: =ROUND(G19*G20,0)
A22: Standard 社数 | C22: =C19-C21 | D22: =D19-D21 | E22: =E19-E21 | F22: =F19-F21 | G22: =G19-G21
A23: 積み上げACV（万円） | C23: =IF(C19=0,0,(C21*$E$12+C22*$E$13)/C19+$C$15) | D23: =IF(D19=0,0,(D21*$E$12+D22*$E$13)/D19+$C$15) | E23: =IF(E19=0,0,(E21*$E$12+E22*$E$13)/E19+$C$15) | F23: =IF(F19=0,0,(F21*$E$12+F22*$E$13)/F19+$C$15) | G23: =IF(G19=0,0,(G21*$E$12+G22*$E$13)/G19+$C$15) | J23: 一本値ではなく積み上げ
A24: 法人売上（百万円） | C24: =C19*C23/100 | D24: =D19*D23/100 | E24: =E19*E23/100 | F24: =F19*F23/100 | G24: =G19*G23/100
A25: 個人契約数 | C25: 0 | D25: 0 | E25: 2000 | F25: 8000 | G25: 17000 | J25: ★プロクリエイター
A26: 個人ACV（万円） | C26: 12 | D26: 12 | E26: 12 | F26: 12 | G26: 12 | J26: 月1万円（チェックポイント6千＋工程ツール4千）
A27: 個人売上（百万円） | C27: =C25*C26/100 | D27: =D25*D26/100 | E27: =E25*E26/100 | F27: =F25*F26/100 | G27: =G25*G26/100
A29: ②-C 個人セルフサーブ（用途特化・フリーミアム）
A30: 項目 | C30: 1期 | D30: 2期 | E30: 3期 | F30: 4期 | G30: 5期 | J30: 考え方
A31: 登録ユーザー（累計） | C31: 0 | D31: 30000 | E31: 120000 | F31: 280000 | G31: 500000 | J31: ★テンプレートは③-Aの6商品に固定
A32: 有料転換率 | C32: 0 | D32: 0.05 | E32: 0.06 | F32: 0.07 | G32: 0.08 | J32: ★
A33: 有料ユーザー | C33: =ROUND(C31*C32,0) | D33: =ROUND(D31*D32,0) | E33: =ROUND(E31*E32,0) | F33: =ROUND(F31*F32,0) | G33: =ROUND(G31*G32,0)
A34: ARPPU（円/年） | C34: 0 | D34: 4000 | E34: 4000 | F34: 4000 | G34: 4000 | J34: ★都度1,500円/本と月額980円の混合
A35: ②-C 売上（百万円） | C35: =C33*C34/1000000 | D35: =D33*D34/1000000 | E35: =E33*E34/1000000 | F35: =F33*F34/1000000 | G35: =G33*G34/1000000
A36: 年間出力本数（データ） | C36: =ROUND(C33*2.5,0) | D36: =ROUND(D33*2.5,0) | E36: =ROUND(E33*2.5,0) | F36: =ROUND(F33*2.5,0) | G36: =ROUND(G33*2.5,0) | J36: 却下された中間生成物も学習に回る
A38: ② 売上 合計（百万円） | C38: =C24+C27+C35 | D38: =D24+D27+D35 | E38: =E24+E27+E35 | F38: =F24+F27+F35 | G38: =G24+G27+G35
A39: ② 粗利率 | B39: 0.8 | J39: ★ソフトウェア外販の一般水準
A41: ARRベース（継続課金のみ）— Synthesia・HeyGenと同じ土俵で比べるための行
A42: 項目 | C42: 1期 | D42: 2期 | E42: 3期 | F42: 4期 | G42: 5期 | J42: 考え方
A43: 法人ARR / 社（万円） | C43: =IF(C19=0,0,C23-$C$15) | D43: =IF(D19=0,0,D23-$C$15) | E43: =IF(E19=0,0,E23-$C$15) | F43: =IF(F19=0,0,F23-$C$15) | G43: =IF(G19=0,0,G23-$C$15) | J43: 積み上げACVから LoRA個別構築の20万を除く
A44: 法人ARR（百万円） | C44: =C19*C43/100 | D44: =D19*D43/100 | E44: =E19*E43/100 | F44: =F19*F43/100 | G44: =G19*G43/100
A45: ② ARR 合計（百万円） | C45: =C44+C27+C35*$B$47 | D45: =D44+D27+D35*$B$47 | E45: =E44+E27+E35*$B$47 | F45: =F44+F27+F35*$B$47 | G45: =G44+G27+G35*$B$47 | J45: 法人ARR ＋ 個人 ＋ セルフサーブの継続分
A46: 一過性収入（百万円） | C46: =C38-C45 | D46: =D38-D45 | E46: =E38-E45 | F46: =F38-F45 | G46: =G38-G45 | J46: LoRA個別構築とセルフサーブの都度課金
...

Sheet 商品マスタ③
A1: ③ 越境C2C — 商品別
A2: 価格は上限を採用（松田さんの決定）。上限＝日本の発注者の支払意思。下限はクリエイターの留保価格で、下回ると供給が付かないという床。中点は参考。
A3: 商品 | B3: 分類 | C3: 参考 軽い場合 | D3: 標準工数 | E3: 下限（供給） | F3: 上限＝採用価格 | G3: 参考 中点 | H3: 5期件数 | I3: 年間工数 | J3: 5期GMV(百万) | K3: 上限の根拠
A5: SNS用ショート | B5: A | C5: 0.5 | D5: 1.5 | E5: =ROUNDUP('クリエイター経済'!$B$10*D5/(1-$B$28)/500,0)*500 | F5: 10000 | G5: =(E5+F5)/2 | H5: 25000 | I5: =D5*H5 | J5: =F5*H5/1000000 | K5: 個人の動画編集外注 5千〜3万の下側
A6: 誕生日ムービー | B6: A | C6: 1 | D6: 2.5 | E6: =ROUNDUP('クリエイター経済'!$B$10*D6/(1-$B$28)/500,0)*500 | F6: 15000 | G6: =(E6+F6)/2 | H6: 12000 | I6: =D6*H6 | J6: =F6*H6/1000000 | K6: サプライズ動画 数千〜2万
A7: 記念日ムービー | B7: A | C7: 1 | D7: 3 | E7: =ROUNDUP('クリエイター経済'!$B$10*D7/(1-$B$28)/500,0)*500 | F7: 18000 | G7: =(E7+F7)/2 | H7: 8000 | I7: =D7*H7 | J7: =F7*H7/1000000 | K7: 還暦・退職。誕生日より重い
A8: イベント・余興ムービー | B8: A | C8: 2 | D8: 5 | E8: =ROUNDUP('クリエイター経済'!$B$10*D8/(1-$B$28)/500,0)*500 | F8: 30000 | G8: =(E8+F8)/2 | H8: 10000 | I8: =D8*H8 | J8: =F8*H8/1000000 | K8: 二次会・余興 1〜5万
A9: WEBサイト用 | B9: A | C9: 3 | D9: 8 | E9: =ROUNDUP('クリエイター経済'!$B$10*D9/(1-$B$28)/500,0)*500 | F9: 50000 | G9: =(E9+F9)/2 | H9: 6000 | I9: =D9*H9 | J9: =F9*H9/1000000 | K9: 個人事業主のサイト用 3〜10万
A10: ウェディングムービー | B10: A | C10: 5 | D10: 15 | E10: =ROUNDUP('クリエイター経済'!$B$10*D10/(1-$B$28)/500,0)*500 | F10: 80000 | G10: =(E10+F10)/2 | H10: 9000 | I10: =D10*H10 | J10: =F10*H10/1000000 | K10: 結婚式ムービー外注 3〜10万
A11: 会社紹介ショート | B11: B | C11: 6 | D11: 12 | E11: =ROUNDUP('クリエイター経済'!$B$10*D11/(1-$B$28)/500,0)*500 | F11: 120000 | G11: =(E11+F11)/2 | H11: 4000 | I11: =D11*H11 | J11: =F11*H11/1000000 | K11: ①の当社価格50万の1/4
A12: 採用（小規模・1職種） | B12: B | C12: 8 | D12: 16 | E12: =ROUNDUP('クリエイター経済'!$B$10*D12/(1-$B$28)/500,0)*500 | F12: 180000 | G12: =(E12+F12)/2 | H12: 2500 | I12: =D12*H12 | J12: =F12*H12/1000000 | K12: ①の当社価格100万の1/5〜1/6
A13: 商品・サービス紹介 | B13: B | C13: 6 | D13: 14 | E13: =ROUNDUP('クリエイター経済'!$B$10*D13/(1-$B$28)/500,0)*500 | F13: 150000 | G13: =(E13+F13)/2 | H13: 5000 | I13: =D13*H13 | J13: =F13*H13/1000000 | K13: 機能数で振れる
A14: 店舗・施設紹介 | B14: B | C14: 5 | D14: 10 | E14: =ROUNDUP('クリエイター経済'!$B$10*D14/(1-$B$28)/500,0)*500 | F14: 100000 | G14: =(E14+F14)/2 | H14: 3500 | I14: =D14*H14 | J14: =F14*H14/1000000 | K14: 撮影なし・生成のみ
A15: 展示会・イベント告知 | B15: B | C15: 4 | D15: 9 | E15: =ROUNDUP('クリエイター経済'!$B$10*D15/(1-$B$28)/500,0)*500 | F15: 80000 | G15: =(E15+F15)/2 | H15: 2000 | I15: =D15*H15 | J15: =F15*H15/1000000 | K15: ①の当社価格30万の1/4
A16: SNS広告用（縦型3本） | B16: B | C16: 6 | D16: 12 | E16: =ROUNDUP('クリエイター経済'!$B$10*D16/(1-$B$28)/500,0)*500 | F16: 120000 | G16: =(E16+F16)/2 | H16: 6000 | I16: =D16*H16 | J16: =F16*H16/1000000 | K16: 3本セット
... A18: 企業オーダーメイド | B18: C | C18: 10 | D18: 50 | E18: =ROUNDUP('クリエイター経済'!$B$10*D18/(1-$B$28)/500,0)*500 | F18: 1000000 | G18: =(E18+F18)/2 | H18: 8900 | I18: =D18*H18 | J18: =F18*H18/1000000 | K18: 上限100万。月742件
A20: 小計 ③-A 個人パッケージ | B20: A | H20: =SUMIF($B$5:$B$18,"A",H$5:H$18) | I20: =SUMIF($B$5:$B$18,"A",I$5:I$18) | J20: =SUMIF($B$5:$B$18,"A",J$5:J$18)
A21: 小計 ③-B 中小企業 | B21: B | H21: =SUMIF($B$5:$B$18,"B",H$5:H$18) | I21: =SUMIF($B$5:$B$18,"B",I$5:I$18) | J21: =SUMIF($B$5:$B$18,"B",J$5:J$18)
A22: 小計 ③-C オーダーメイド | B22: C | H22: =SUMIF($B$5:$B$18,"C",H$5:H$18) | I22: =SUMIF($B$5:$B$18,"C",I$5:I$18) | J22: =SUMIF($B$5:$B$18,"C",J$5:J$18)
A23: 合計（②-Cの共食い前） | H23: =SUM(H20:H22) | I23: =SUM(I20:I22) | J23: =SUM(J20:J22)
A24: − ②-Cセルフサーブによる共食い（③-A） | J24: =-J20*G35 | K24: ③-Aの安い帯が②-Cに流れる分。下の期別GMVはこれを引いた後
A25: 5期GMV（共食い後）＝下の期別G列と一致 | J25: =J23+J24
A27: 手数料と原価率
A28: 手数料率 | B28: 0.3 | K28: 一律30%。70%をクリエイターに渡す（松田さん決定）
A29: 決済手数料率 | B29: 0.0318 | K29: Stripe 国内カード3.6%／銀行振込1.5% を 80:20 で加重
A30: 期別 | B30: 0.03 | K30: 中国の制作パートナー経由（松田さん指示）
A31: 項目 | C31: 1期 | D31: 2期 | E31: 3期 | F31: 4期 | G31: 5期 | J31: 考え方
A32: ランプ ③-A | C32: 0.01 | D32: 0.07 | E32: 0.28 | F32: 0.62 | G32: 1 | K32: 1期から。仲介が要らない
A33: ランプ ③-B | C33: 0 | D33: 0.04 | E33: 0.22 | F33: 0.58 | G33: 1 | K33: 2期から
A34: ランプ ③-C | C34: 0 | D34: 0 | E34: 0.15 | F34: 0.55 | G34: 1 | K34: 3期から。AI-botの開発後
A35: ②-Cセルフサーブの共食い係数 | C35: 0 | D35: 0.007 | E35: 0.032 | F35: 0.088 | G35: 0.18 | K35: ③-Aの件数に対して
A36: ③-A GMV（百万円） | C36: =$J$20*C32*(1-C35) | D36: =$J$20*D32*(1-D35) | E36: =$J$20*E32*(1-E35) | F36: =$J$20*F32*(1-F35) | G36: =$J$20*G32*(1-G35)
A37: ③-B GMV（百万円） | C37: =$J$21*C33 | D37: =$J$21*D33 | E37: =$J$21*E33 | F37: =$J$21*F33 | G37: =$J$21*G33
A38: ③-C GMV（百万円） | C38: =$J$22*C34 | D38: =$J$22*D34 | E38: =$J$22*E34 | F38: =$J$22*F34 | G38: =$J$22*G34
A39: GMV 合計 | C39: =C36+C37+C38 | D39: =D36+D37+D38 | E39: =E36+E37+E38 | F39: =F36+F37+F38 | G39: =G36+G37+G38
A40: 取引件数 | C40: =$H$20*C32*(1-C35)+$H$21*C33+$H$22*C34 | D40: =$H$20*D32*(1-D35)+$H$21*D33+$H$22*D34 | E40: =$H$20*E32*(1-E35)+$H$21*E33+$H$22*E34 | F40: =$H$20*F32*(1-F35)+$H$21*F33+$H$22*F34 | G40: =$H$20*G32*(1-G35)+$H$21*G33+$H$22*G34
A41: ③ 売上（手数料30%） | C41: =C39*$B$28 | D41: =D39*$B$28 | E41: =E39*$B$28 | F41: =F39*$B$28 | G41: =G39*$B$28
A42: − 決済・送金・システム | C42: =C39*($B$29+$B$30)+C40*'システム原価'!$H$29/1000000 | D42: =D39*($B$29+$B$30)+D40*'システム原価'!$H$29/1000000 | E42: =E39*($B$29+$B$30)+E40*'システム原価'!$H$29/1000000 | F42: =F39*($B$29+$B$30)+F40*'システム原価'!$H$29/1000000 | G42: =G39*($B$29+$B$30)+G40*'システム原価'!$H$29/1000000
A43: 売上総利益 | C43: =C41-C42 | D43: =D41-D42 | E43: =E41-E42 | F43: =F41-F42 | G43: =G41-G42
A44: 年間工数（時間） | C44: =$I$20*C32*(1-C35)+$I$21*C33+$I$22*C34 | D44: =$I$20*D32*(1-D35)+$I$21*D33+$I$22*D34 | E44: =$I$20*E32*(1-E35)+$I$21*E33+$I$22*E34 | F44: =$I$20*F32*(1-F35)+$I$21*F33+$I$22*F34 | G44: =$I$20*G32*(1-G35)+$I$21*G33+$I$22*G34
...

Sheet 人員と人件費
A1: 人員と人件費（社員はPM中心）
A2: 開発は中国・ベトナム・東欧への業務委託。社員として抱えるのはPM。制作ディレクション・CS・オペレーションも業務委託／BPO。管理はAX化で極小。
A3: 職種 | B3: 年収(万円) | C3: 1期 | D3: 2期 | E3: 3期 | F3: 4期 | G3: 5期 | H3: 考え方
A4: 経営・CxO | B4: 900 | C4: 1 | D4: 1 | E4: 2 | F4: 3 | G4: 3 | H4: 代表＋CFO／CTO級
A5: モデル開発PM | B5: 950 | C5: =C41 | D5: =D41 | E5: =E41 | F5: =F41 | G5: =G41 | H5: オフショアチームを率いる。人数はAX後のエンジニア数から逆算
A6: 制作統括 | B6: 650 | C6: 1 | D6: 2 | E6: 3 | F6: 3 | G6: 3 | H6: 業務委託ディレクターの束ね役
A7: 事業開発・アライアンス | B7: 700 | C7: 1 | D7: 2 | E7: 4 | F7: 5 | G7: 6 | H7: 営業体制シートの直販人員と同じ
A8: クリエイターネットワーク統括 | B8: 600 | C8: 1 | D8: 1 | E8: 2 | F8: 3 | G8: 3 | H8: 中国パートナー・登録クリエイター管理
A9: 管理・コーポレート | B9: 550 | C9: 0 | D9: 1 | E9: 1 | F9: 2 | G9: 3 | H9: AX化で極小。取引処理はBPO、専門領域は社外の顧問
A10: 社員数 合計 | C10: =SUM(C4:C9) | D10: =SUM(D4:D9) | E10: =SUM(E4:E9) | F10: =SUM(F4:F9) | G10: =SUM(G4:G9)
A11: 人件費（百万円） | C11: =SUMPRODUCT($B$4:$B$9,C4:C9)*'前提'!$C$17/100 | D11: =SUMPRODUCT($B$4:$B$9,D4:D9)*'前提'!$D$17/100 | E11: =SUMPRODUCT($B$4:$B$9,E4:E9)*'前提'!$E$17/100 | F11: =SUMPRODUCT($B$4:$B$9,F4:F9)*'前提'!$F$17/100 | G11: =SUMPRODUCT($B$4:$B$9,G4:G9)*'前提'!$G$17/100
A12: 1人あたり人件費（万円） | C12: =IF(C10=0,0,C11*100/C10) | D12: =IF(D10=0,0,D11*100/D10) | E12: =IF(E10=0,0,E11*100/E10) | F12: =IF(F10=0,0,F11*100/F10) | G12: =IF(G10=0,0,G11*100/G10)
A14: 参考：社員ではない人たち
A15: 区分 | C15: 1期 | D15: 2期 | E15: 3期 | F15: 4期 | G15: 5期 | H15: 考え方
A16: 業務委託ディレクション（人） | C16: ='商品マスタ①'!I12*(1/120+1/90)*'商品マスタ①'!I10/'前提'!$C$4 | D16: ='商品マスタ①'!J12*(1/120+1/90)*'商品マスタ①'!J10/'前提'!$D$4 | E16: ='商品マスタ①'!K12*(1/120+1/90)*'商品マスタ①'!K10/'前提'!$E$4 | F16: ='商品マスタ①'!L12*(1/120+1/90)*'商品マスタ①'!L10/'前提'!$F$4 | G16: ='商品マスタ①'!M12*(1/120+1/90)*'商品マスタ①'!M10/'前提'!$G$4 | H16: 本数 ×（1/120＋1/90）× 難度 ÷ AX倍率
A17: 中国クリエイター 必要稼働（人） | C17: =('商品マスタ③'!C44+'商品マスタ①'!I15*1000000/4000)/1800 | D17: =('商品マスタ③'!D44+'商品マスタ①'!J15*1000000/4000)/1800 | E17: =('商品マスタ③'!E44+'商品マスタ①'!K15*1000000/4000)/1800 | F17: =('商品マスタ③'!F44+'商品マスタ①'!L15*1000000/4000)/1800 | G17: =('商品マスタ③'!G44+'商品マスタ①'!M15*1000000/4000)/1800 | H17: （③の年間工数 ＋ ①のクリエイター支払÷実効時給4,000円）÷ 年1,800時間
A18: 中国クリエイター 登録（人） | C18: 30 | D18: 120 | E18: 500 | F18: 1200 | G18: 2000 | H18: ★採用計画。1期30名は松田さんの指示。工数から導出される数ではない
A19: 稼働率 | C19: =IF(C18=0,0,C17/C18) | D19: =IF(D18=0,0,D17/D18) | E19: =IF(E18=0,0,E17/E18) | F19: =IF(F18=0,0,F17/F18) | G19: =IF(G18=0,0,G17/G18) | H19: 必要稼働 ÷ 登録。立ち上げ期は低く、市場が育つと上がる
A21: ⚠ 登録数は工数から出る数字ではなく採用計画。先に人を集めないと受注できないので、立ち上げ期は必要稼働より多く抱える。5年で約2,000名（中国の微短劇就業者69万人の0.3%）。年400〜800名を新規登録させる採用オペレーションが要る。
A23: オフショア開発（業務委託）— ベトナム内のピラミッド
A24: 国・職位 | B24: 月額(万) | C24: 構成比 | H24: 出所・考え方
A25: ベトナム ブリッジSE | B25: 59 | C25: 0.2 | H25: オフショア開発.com 2026。レビューと設計を担う上位層
A26: ベトナム プログラマー | B26: 40.1 | C26: 0.8 | H26: 同上。実装を担う
A27: インド ブリッジSE | B27: 60 | C27: 0 | H27: 参考。上位層で入れる場合
A28: インド プログラマー | B28: 37.5 | C28: 0 | H28: 参考。ミドルを別国にすると継ぎ目が増える
A29: 中国 シニア | B29: 71.7 | C29: 0 | H29: 参考。ベトナムBSEより21%高い
A30: 東欧 シニア | B30: 104 | C30: 0 | H30: 参考。最も高い
A31: 構成比 合計 | C31: =SUM(C25:C30)
A32: 加重単価（万円/年） | B32: =SUMPRODUCT(B25:B30,C25:C30)*12 | H32: ブリッジSE 20% ＋ プログラマー 80%
A33: ⚠ ピラミッドはベトナム内で組む。シニアがミドルをレビューする接点は最もコミュニケーション量が多いので、そこに国・言語・ベンダーの継ぎ目を置かない。社員PMの下が2層で収まる。
A34: ⚠ 安い順は ミャンマー(40)＜インド(45)＜フィリピン(47.5)＜ベトナム(50)＜中国(71.7)＜東欧(104)。ロシア・ベラルーシは外為法の役務取引規制（2022/3/18〜）で対象外。単価の問題ではない。
A36: エンジニアのAX化 — 人数を減らして単価の高い層に寄せる
A37: 項目 | C37: 1期 | D37: 2期 | E37: 3期 | F37: 4期 | G37: 5期 | H37: 考え方
A38: 必要開発工数（AXなし換算・人年） | C38: 5 | D38: 10 | E38: 20 | F38: 30 | G38: 40 | H38: ★プロダクト規模から
A39: ★ エンジニアのAX倍率 | C39: 1 | D39: 1.2 | E39: 1.5 | F39: 1.9 | G39: 2.2 | H39: ★ミドル中心なのでレビューがボトルネックになる。制作(4.0)より低く置く
A40: 実エンジニア数（委託） | C40: =ROUNDUP(C38/C39,0) | D40: =ROUNDUP(D38/D39,0) | E40: =ROUNDUP(E38/E39,0) | F40: =ROUNDUP(F38/F39,0) | G40: =ROUNDUP(G38/G39,0) | H40: 必要工数 ÷ AX倍率
A41: PM（社員） | C41: =ROUNDUP(C40/5,0) | D41: =ROUNDUP(D40/5,0) | E41: =ROUNDUP(E40/5,0) | F41: =ROUNDUP(F40/5,0) | G41: =ROUNDUP(G40/5,0) | H41: 1名で5名を見る。上の人件費表はここを参照
A42: 開発委託費（百万円） | C42: =C40*$B$32/100 | D42: =D40*$B$32/100 | E42: =E40*$B$32/100 | F42: =F40*$B$32/100 | G42: =G40*$B$32/100 | H42: 実人数 × 加重単価
A44: 旧構成は社員40名。PM4名＋委託19名になる。加重単価は年527万で、中国シニア20%＋ベトナムミドル80%（557万）より安く、継ぎ目もない。
A45: ⚠ 管理・コーポレート3名は、5期に上場会社として内部統制報告制度の対象になる規模には薄い。取引処理はBPOに出す前提だが、内部統制の設計・運用・評価は社員の仕事。監査法人と主幹事に早期に当てること。★確認事項
...

Sheet 損益計算書
A1: 5年損益計算書（単位：百万円）
A2: 全て数式。商品マスタ①②③・営業体制・人員・システム原価を参照している。
A3: 項目 | C3: 1期 | D3: 2期 | E3: 3期 | F3: 4期 | G3: 5期 | H3: 備考
A4: ① 映像制作 | C4: ='商品マスタ①'!I13 | D4: ='商品マスタ①'!J13 | E4: ='商品マスタ①'!K13 | F4: ='商品マスタ①'!L13 | G4: ='商品マスタ①'!M13 | H4: 4商品の積み上げ（商品マスタ①）
A5: 受注本数（本） | C5: ='商品マスタ①'!I12 | D5: ='商品マスタ①'!J12 | E5: ='商品マスタ①'!K12 | F5: ='商品マスタ①'!L12 | G5: ='商品マスタ①'!M12 | H5: 営業体制からの積み上げ
A6: 平均単価（万円） | C6: ='商品マスタ①'!I9 | D6: ='商品マスタ①'!J9 | E6: ='商品マスタ①'!K9 | F6: ='商品マスタ①'!L9 | G6: ='商品マスタ①'!M9
A7: 平均難度係数 | C7: ='商品マスタ①'!I10 | D7: ='商品マスタ①'!J10 | E7: ='商品マスタ①'!K10 | F7: ='商品マスタ①'!L10 | G7: ='商品マスタ①'!M10
A8: 1本あたり原価（万円） | C8: ='商品マスタ①'!I11 | D8: ='商品マスタ①'!J11 | E8: ='商品マスタ①'!K11 | F8: ='商品マスタ①'!L11 | G8: ='商品マスタ①'!M11
A9: AX倍率 | C9: ='前提'!$C$4 | D9: ='前提'!$D$4 | E9: ='前提'!$E$4 | F9: ='前提'!$F$4 | G9: ='前提'!$G$4
A10: ② ツール外販 | C10: ='商品マスタ②'!C38 | D10: ='商品マスタ②'!D38 | E10: ='商品マスタ②'!E38 | F10: ='商品マスタ②'!F38 | G10: ='商品マスタ②'!G38 | H10: 法人2階建て＋個人＋セルフサーブ
A11: ③ C2C手数料 | C11: ='商品マスタ③'!C41 | D11: ='商品マスタ③'!D41 | E11: ='商品マスタ③'!E41 | F11: ='商品マスタ③'!F41 | G11: ='商品マスタ③'!G41 | H11: 14商品。GMV × 手数料30%
A12: 売上高 | C12: =C4+C10+C11 | D12: =D4+D10+D11 | E12: =E4+E10+E11 | F12: =F4+F10+F11 | G12: =G4+G10+G11
A14: ① 売上原価 | C14: =C5*C8/100 | D14: =D5*D8/100 | E14: =E5*E8/100 | F14: =F5*F8/100 | G14: =G5*G8/100
A15: ① 売上総利益 | C15: =C4-C14 | D15: =D4-D14 | E15: =E4-E14 | F15: =F4-F14 | G15: =G4-G14
A16: ② 売上総利益 | C16: =C10*'商品マスタ②'!$B$39 | D16: =D10*'商品マスタ②'!$B$39 | E16: =E10*'商品マスタ②'!$B$39 | F16: =F10*'商品マスタ②'!$B$39 | G16: =G10*'商品マスタ②'!$B$39
A17: ③ 売上総利益 | C17: ='商品マスタ③'!C43 | D17: ='商品マスタ③'!D43 | E17: ='商品マスタ③'!E43 | F17: ='商品マスタ③'!F43 | G17: ='商品マスタ③'!G43 | H17: 30%から決済・送金・システム原価を引いた後
A18: 売上総利益 | C18: =C15+C16+C17 | D18: =D15+D16+D17 | E18: =E15+E16+E17 | F18: =F15+F16+F17 | G18: =G15+G16+G17
A19: 粗利率 | C19: =IF(C12=0,0,C18/C12) | D19: =IF(D12=0,0,D18/D12) | E19: =IF(E12=0,0,E18/E12) | F19: =IF(F12=0,0,F18/F12) | G19: =IF(G12=0,0,G18/G12)
A21: 人件費（社員） | C21: ='人員と人件費'!C11 | D21: ='人員と人件費'!D11 | E21: ='人員と人件費'!E11 | F21: ='人員と人件費'!F11 | G21: ='人員と人件費'!G11
A22: 開発委託費（オフショア） | C22: ='人員と人件費'!C42 | D22: ='人員と人件費'!D42 | E22: ='人員と人件費'!E42 | F22: ='人員と人件費'!F42 | G22: ='人員と人件費'!G42 | H22: 中国・ベトナム・東欧。PM1名あたり5名
A23: 研究開発費（GPU・基盤） | C23: ='前提'!$C$9 | D23: ='前提'!$D$9 | E23: ='前提'!$E$9 | F23: ='前提'!$F$9 | G23: ='前提'!$G$9 | H23: クラウドGPU・ライセンス・データ基盤
A24: BPO（CS・運用） | C24: ='前提'!$C$10 | D24: ='前提'!$D$10 | E24: ='前提'!$E$10 | F24: ='前提'!$F$10 | G24: ='前提'!$G$10
A25: 獲得費 | C25: =C4*'前提'!$C$12+C10*'前提'!$C$13+'前提'!$C$11 | D25: =D4*'前提'!$D$12+D10*'前提'!$D$13+'前提'!$D$11 | E25: =E4*'前提'!$E$12+E10*'前提'!$E$13+'前提'!$E$11 | F25: =F4*'前提'!$F$12+F10*'前提'!$F$13+'前提'!$F$11 | G25: =G4*'前提'!$G$12+G10*'前提'!$G$13+'前提'!$G$11
A26: 代理店手数料 | C26: =C4*'前提'!$C$14*'前提'!$C$15 | D26: =D4*'前提'!$D$14*'前提'!$D$15 | E26: =E4*'前提'!$E$14*'前提'!$E$15 | F26: =F4*'前提'!$F$14*'前提'!$F$15 | G26: =G4*'前提'!$G$14*'前提'!$G$15 | H26: ①の代理店チャネル分のみ
A27: その他販管費 | C27: =C12*'前提'!$C$16 | D27: =D12*'前提'!$D$16 | E27: =E12*'前提'!$E$16 | F27: =F12*'前提'!$F$16 | G27: =G12*'前提'!$G$16
A28: 販売費・一般管理費 計 | C28: =SUM(C21:C27) | D28: =SUM(D21:D27) | E28: =SUM(E21:E27) | F28: =SUM(F21:F27) | G28: =SUM(G21:G27)
A29: 営業利益 | C29: =C18-C28 | D29: =D18-D28 | E29: =E18-E28 | F29: =F18-F28 | G29: =G18-G28
A30: 営業利益率 | C30: =IF(C12=0,0,C29/C12) | D30: =IF(D12=0,0,D29/D12) | E30: =IF(E12=0,0,E29/E12) | F30: =IF(F12=0,0,F29/F12) | G30: =IF(G12=0,0,G29/G12)
A32: 投資家が見る指標
A33: 社員数 | C33: ='人員と人件費'!C10 | D33: ='人員と人件費'!D10 | E33: ='人員と人件費'!E10 | F33: ='人員と人件費'!F10 | G33: ='人員と人件費'!G10
A34: 売上 / 社員（万円） | C34: =IF(C33=0,0,C12*100/C33) | D34: =IF(D33=0,0,D12*100/D33) | E34: =IF(E33=0,0,E12*100/E33) | F34: =IF(F33=0,0,F12*100/F33) | G34: =IF(G33=0,0,G12*100/G33) | H34: 国内SaaSの平均2,000〜4,000万との比較
A35: 研究開発費 ÷ 売上 | C35: =IF(C12=0,0,C23/C12) | D35: =IF(D12=0,0,D23/D12) | E35: =IF(E12=0,0,E23/E12) | F35: =IF(F12=0,0,F23/F12) | G35: =IF(G12=0,0,G23/G12)
A36: 人手に比例しない収益 | C36: =C10+C11+C4*(1-1/'前提'!$C$4) | D36: =D10+D11+D4*(1-1/'前提'!$D$4) | E36: =E10+E11+E4*(1-1/'前提'!$E$4) | F36: =F10+F11+F4*(1-1/'前提'!$F$4) | G36: =G10+G11+G4*(1-1/'前提'!$G$4) | H36: ②＋③＋①のうちAXで人手から切れた分
A37: 同 比率 | C37: =IF(C12=0,0,C36/C12) | D37: =IF(D12=0,0,D36/D12) | E37: =IF(E12=0,0,E36/E12) | F37: =IF(F12=0,0,F36/F12) | G37: =IF(G12=0,0,G36/G12) | H37: 受託と読まれないための中心指標
A38: 顧客が浮かせる額 | C38: ='商品マスタ①'!I14 | D38: ='商品マスタ①'!J14 | E38: ='商品マスタ①'!K14 | F38: ='商品マスタ①'!L14 | G38: ='商品マスタ①'!M14 | H38: ①の提案の中身。値引き額の総額

Sheet 資金計画
A1: 資金計画・キャッシュフロー（単位：百万円）
A2: 営業利益からキャッシュ残高まで。運転資本と法人税を引いた後の、実際に手元に残る現金。
A3: 項目 | C3: 1期 | D3: 2期 | E3: 3期 | F3: 4期 | G3: 5期 | H3: 備考
A4: 営業利益 | C4: ='損益計算書'!C29 | D4: ='損益計算書'!D29 | E4: ='損益計算書'!E29 | F4: ='損益計算書'!F29 | G4: ='損益計算書'!G29
A5: 繰越欠損金（期首） | C5: =0 | D5: =MAX(0,C5-C4) | E5: =MAX(0,D5-D4) | F5: =MAX(0,E5-E4) | G5: =MAX(0,F5-F4) | H5: 前期までの累積赤字
A6: 課税所得 | C6: =MAX(0,C4-C5) | D6: =MAX(0,D4-D5) | E6: =MAX(0,E4-E5) | F6: =MAX(0,F4-F5) | G6: =MAX(0,G4-G5)
A7: 法人税等 | C7: =C6*'前提'!$C$18 | D7: =D6*'前提'!$D$18 | E7: =E6*'前提'!$E$18 | F7: =F6*'前提'!$F$18 | G7: =G6*'前提'!$G$18 | H7: 実効税率30%。繰越欠損金の控除後
A9: 運転資本：①制作（売掛−買掛） | C9: ='損益計算書'!C4*'前提'!$C$19/365-'損益計算書'!C14*'前提'!$C$20/365 | D9: ='損益計算書'!D4*'前提'!$D$19/365-'損益計算書'!D14*'前提'!$D$20/365 | E9: ='損益計算書'!E4*'前提'!$E$19/365-'損益計算書'!E14*'前提'!$E$20/365 | F9: ='損益計算書'!F4*'前提'!$F$19/365-'損益計算書'!F14*'前提'!$F$20/365 | G9: ='損益計算書'!G4*'前提'!$G$19/365-'損益計算書'!G14*'前提'!$G$20/365 | H9: 入金60日・支払30日。伸びるほど現金が先に出る
A10: 運転資本：②前受金（△） | C10: =-'損益計算書'!C10*'前提'!$C$21/365 | D10: =-'損益計算書'!D10*'前提'!$D$21/365 | E10: =-'損益計算書'!E10*'前提'!$E$21/365 | F10: =-'損益計算書'!F10*'前提'!$F$21/365 | G10: =-'損益計算書'!G10*'前提'!$G$21/365 | H10: 年額一括前受。資金の source になる
A11: 運転資本 残高 計 | C11: =C9+C10 | D11: =D9+D10 | E11: =E9+E10 | F11: =F9+F10 | G11: =G9+G10
A12: 運転資本の増減（△は流出） | C12: =-C11 | D12: =-(D11-C11) | E12: =-(E11-D11) | F12: =-(F11-E11) | G12: =-(G11-F11)
A14: 営業キャッシュフロー | C14: =C4-C7+C12 | D14: =D4-D7+D12 | E14: =E4-E7+E12 | F14: =F4-F7+F12 | G14: =G4-G7+G12
A15: 投資キャッシュフロー | C15: =-'前提'!$C$22 | D15: =-'前提'!$D$22 | E15: =-'前提'!$E$22 | F15: =-'前提'!$F$22 | G15: =-'前提'!$G$22 | H15: クラウド前提。自社設備を持たない
A16: 調達：シード | C16: ='前提'!$C$23 | D16: ='前提'!$D$23 | E16: ='前提'!$E$23 | F16: ='前提'!$F$23 | G16: ='前提'!$G$23
A17: 調達：シリーズA | C17: ='前提'!$C$24 | D17: ='前提'!$D$24 | E17: ='前提'!$E$24 | F17: ='前提'!$F$24 | G17: ='前提'!$G$24
A18: 調達：借入 | C18: ='前提'!$C$25 | D18: ='前提'!$D$25 | E18: ='前提'!$E$25 | F18: ='前提'!$F$25 | G18: ='前提'!$G$25
A19: 財務キャッシュフロー | C19: =C16+C17+C18 | D19: =D16+D17+D18 | E19: =E16+E17+E18 | F19: =F16+F17+F18 | G19: =G16+G17+G18
A21: 当期キャッシュ増減 | C21: =C14+C15+C19 | D21: =D14+D15+D19 | E21: =E14+E15+E19 | F21: =F14+F15+F19 | G21: =G14+G15+G19
A22: 期末キャッシュ残高 | C22: =C21 | D22: =C22+D21 | E22: =D22+E21 | F22: =E22+F21 | G22: =F22+G21 | H22: マイナスになる期があってはいけない
A23: 月次バーン（平均） | C23: =IF(C14>=0,0,-C14/12) | D23: =IF(D14>=0,0,-D14/12) | E23: =IF(E14>=0,0,-E14/12) | F23: =IF(F14>=0,0,-F14/12) | G23: =IF(G14>=0,0,-G14/12)
A24: （感応度）前受金ゼロなら期末残高 | C24: =C22+C10 | D24: =D22+D10 | E24: =E22+E10 | F24: =F22+F10 | G24: =G22+G10 | H24: ツールを月額課金にした場合

Sheet 資本構成の推移
A1: 株式シェアの推移（設立 → 上場）
A2: 出所は CAP_TABLE.md 第5章。J-KISS はポストマネー・キャップなので、転換時のシード持分は 調達額 ÷ キャップ。
A3: 項目 | C3: 値 | D3: 単位 | E3: 区分 | J3: 備考
B4: 資本金 | C4: 800 | D4: 万円 | E4: 確定 | J4: 代表個人が全額出資
B5: ESOP枠（設立時） | C5: 0.1 | D5: % | E5: 計画 | J5: 後から作ると全員の希薄化になるので設立時に設計
B6: J-KISS キャップ（ポストマネー） | C6: 6 | D6: 億円 | E6: 確定 | J6: 交渉帯6〜10億
B7: シード調達額 | C7: 1.42 | D7: 億円 | E7: 確定 | J7: 目標1.5億のうち0.08億は代表個人
B8: ディスカウント | C8: 0.2 | D8: % | E8: 確定 | J8: キャップとの有利な方
B9: シリーズA ポストマネー評価 | C9: 15 | D9: 億円 | E9: 計画 | J9: 2028年（2期）
B10: シリーズA 調達額 | C10: 3 | D10: 億円 | E10: 計画 | J10: 無いと2期末に資金ショート
B11: ESOP補充後の ESOP比率 | C11: 0.099 | D11: % | E11: 計画 | J11: シリーズAで薄まった枠を戻す
B12: IPO 公募比率 | C12: 0.2 | D12: % | E12: 計画 | J12: 新株発行なので全員が薄まる
B13: IPO 売出し（シードから） | C13: 0.055 | D13: % | E13: 計画 | J13: 既存株主が売る。創業者は薄まらない
B14: IPO 売出し（シリーズAから） | C14: 0 | D14: % | E14: 計画 | J14: シード分だけで基準を満たす
B15: 転換時のシード持分 | C15: =C7/C6 | J15: ポストマネー・キャップなので 1.42 ÷ 6
B16: シリーズA の持分 | C16: =C10/C9 | J16: 3億 ÷ post 15億
A18: 持分の推移
A19: 時期 | B19: イベント | C19: 金額 | D19: 創業者 | E19: ESOP | F19: シード | G19: シリーズA | H19: 公募 | I19: 合計 | J19: 経営権の判定
A20: 2026/10 | B20: 設立（資本金800万） | C20: — | D20: =1 | E20: =0 | F20: =0 | G20: =0 | H20: =0 | I20: =SUM(D20:H20) | J20: =IF(D20>0.5,"経営権あり（50%超）",IF(D20>0.334,"拒否権あり（1/3超）","1/3割れ"))
A21: 2026/10 | B21: ESOP枠を設計 | C21: — | D21: =D20*(1-$C$5) | E21: =$C$5 | F21: =0 | G21: =0 | H21: =0 | I21: =SUM(D21:H21) | J21: =IF(D21>0.5,"経営権あり（50%超）",IF(D21>0.334,"拒否権あり（1/3超）","1/3割れ"))
A22: 2026/10 | B22: J-KISS 発行（未転換） | C22: 1.42億 | D22: =D21 | E22: =E21 | F22: =0 | G22: =0 | H22: =0 | I22: =SUM(D22:H22) | J22: =IF(D22>0.5,"経営権あり（50%超）",IF(D22>0.334,"拒否権あり（1/3超）","1/3割れ"))
A23: 2028 | B23: シリーズA ＋ J-KISS転換 | C23: 3億 | D23: =D22*(1-$C$15)*(1-$C$16) | E23: =E22*(1-$C$15)*(1-$C$16) | F23: =$C$15*(1-$C$16) | G23: =$C$16 | H23: =0 | I23: =SUM(D23:H23) | J23: =IF(D23>0.5,"経営権あり（50%超）",IF(D23>0.334,"拒否権あり（1/3超）","1/3割れ"))
A24: 2028 | B24: ESOP補充 | C24: — | D24: =D23*(1-$C$11)/(1-E23) | E24: =$C$11 | F24: =F23*(1-$C$11)/(1-E23) | G24: =G23*(1-$C$11)/(1-E23) | H24: =0 | I24: =SUM(D24:H24) | J24: =IF(D24>0.5,"経営権あり（50%超）",IF(D24>0.334,"拒否権あり（1/3超）","1/3割れ"))
A25: 2031 | B25: IPO 公募 | C25: — | D25: =D24*(1-$C$12) | E25: =E24*(1-$C$12) | F25: =F24*(1-$C$12) | G25: =G24*(1-$C$12) | H25: =$C$12 | I25: =SUM(D25:H25) | J25: =IF(D25>0.5,"経営権あり（50%超）",IF(D25>0.334,"拒否権あり（1/3超）","1/3割れ"))
A26: 2031 | B26: 売出し（既存株主が売る） | C26: — | D26: =D25 | E26: =E25 | F26: =F25-$C$13 | G26: =G25-$C$14 | H26: =H25+$C$13+$C$14 | I26: =SUM(D26:H26) | J26: =IF(D26>0.5,"経営権あり（50%超）",IF(D26>0.334,"拒否権あり（1/3超）","1/3割れ"))
A28: 流通株式比率 — 基準25%を満たす設計
A29: 株主 | B29: 上場後の保有 | C29: 10%の判定 | D29: 流通株式への算入 | E29: 算入される持分 | J29: 理由
A30: 創業者（役員） | B30: =D26 | C30: — | D30: × 除外 | E30: 0 | J30: 役員の保有分は除外
A31: ESOP枠 | B31: =E26 | C31: — | D31: × 除外 | E31: 0 | J31: 役員・従業員分は除外
A32: シード投資家 保有分 | B32: =F26 | C32: =IF(B32<0.1,"10%未満","10%以上") | D32: =IF(B32<0.1,"○ 算入","× 除外") | E32: =IF(B32<0.1,B32,0) | J32: 10%未満なら全株が算入。売出しでここを越える
A33: シリーズA 保有分 | B33: =G26 | C33: =IF(B33<0.1,"10%未満","10%以上") | D33: =IF(B33<0.1,"○ 算入","× 除外") | E33: =IF(B33<0.1,B33,0) | J33: 10%以上なので除外
A34: 公募・売出し | B34: =H26 | C34: — | D34: ○ 算入 | E34: =B34 | J34: 市場に出た分
A35: 流通株式比率 | E35: =SUM(E30:E34)
A36: 基準25%に対する過不足 | D36: =IF(E35>=0.25,"○ 満たす","× 不足") | E36: =E35-0.25
A38: シードが5.5%を売出すと保有が10%未満になり、残りの保有株も一括で算入される。公募を25%に上げる案より創業者持分が2.6ポイント厚く残る（42.2% vs 39.5%）。

Sheet 資本政策とリターン
A1: 資本政策とシード投資家のリターン
A2: ⚠ 事業計画からの逆算であって、投資の推奨でも利回りの保証でもない。計画が達成された場合の数字。
A3: 項目 | B3: 値 | C3: 単位 | D3: 区分 | I3: 備考
A4: J-KISS キャップ（ポストマネー） | B4: ='資本構成の推移'!C6 | C4: 億円 | D4: 確定
A5: シード調達額 | B5: ='資本構成の推移'!C7 | C5: 億円 | D5: 確定 | I5: 残り0.08億は代表個人
A6: 転換時のシード持分 | B6: ='資本構成の推移'!C15 | C6: % | D6: 計算 | I6: ＝ 調達額 ÷ キャップ
A7: 転換後の希薄化 | B7: =B8/B6 | C7: 倍 | D7: 計算 | I7: シリーズA→ESOP補充→IPO公募 の積
A8: 上場後のシード持分 | B8: ='資本構成の推移'!F25 | C8: % | D8: 計算 | I8: 売出し分を含む経済持分。CAP_TABLE 第5章
A9: 出資 → 上場 | B9: 4.9 | C9: 年 | D9: 計画 | I9: 2026年10月 → 2031年9月 東証グロース
A11: ① ライン別に倍率を分けた場合（証券会社が実際にやる見方）
A12: ケース | B12: ツール倍率 | C12: C2C倍率 | D12: 制作倍率 | E12: 時価総額(億) | F12: 取り分(億) | G12: 倍率 | H12: IRR | I12: 考え方
A13: 保守 | B13: 6 | C13: 4 | D13: 1.5 | E13: =('損益計算書'!$G$10*B13+'損益計算書'!$G$11*C13+'損益計算書'!$G$4*D13)/100 | F13: =E13*$B$8 | G13: =F13/$B$5 | H13: =G13^(1/$B$9)-1 | I13: 人手に比例しない90%超を根拠にツールへSaaS寄りの倍率
A14: 中庸 | B14: 7 | C14: 5 | D14: 2 | E14: =('損益計算書'!$G$10*B14+'損益計算書'!$G$11*C14+'損益計算書'!$G$4*D14)/100 | F14: =E14*$B$8 | G14: =F14/$B$5 | H14: =G14^(1/$B$9)-1
A15: 強気 | B15: 8 | C15: 6 | D15: 2.5 | E15: =('損益計算書'!$G$10*B15+'損益計算書'!$G$11*C15+'損益計算書'!$G$4*D15)/100 | F15: =E15*$B$8 | G15: =F15/$B$5 | H15: =G15^(1/$B$9)-1 | I15: Synthesia・HeyGenと同じ土俵に立てた場合
A17: ② 全社に PSR を当てた場合
A18: ケース | B18: PSR | E18: 時価総額(億) | F18: 取り分(億) | G18: 倍率 | H18: IRR | I18: 考え方
A19: PSR 4倍 | B19: 4 | E19: ='損益計算書'!$G$12*B19/100 | F19: =E19*$B$8 | G19: =F19/$B$5 | H19: =G19^(1/$B$9)-1 | I19: 人手に比例しない収益が9割であることを根拠にする
A20: PSR 5倍 | B20: 5 | E20: ='損益計算書'!$G$12*B20/100 | F20: =E20*$B$8 | G20: =F20/$B$5 | H20: =G20^(1/$B$9)-1

Sheet 業界ベンチマーク
A1: 実在企業と並べる（5期の当社）
A2: ⚠ 世界の「映像制作会社ランキング」は存在しない。大手広告グループは制作事業を分離開示しないため。
A3: 会社 | B3: 売上(億円) | C3: 区分 | D3: 決算期・出所 | E3: 備考
A4: 東映 | B4: 1853 | C4: 映画・映像製作 | D4: 2026/3期 | E4: 国内最大
A5: IMAGICA GROUP | B5: 1000 | C5: ポスプロ・映像技術 | D5: 2026/3期（Q1 222億からの推計） | E5: 推計値
A6: 東映アニメーション | B6: 937 | C6: アニメ製作 | D6: 2026/3期
A7: AOI TYO Holdings | B7: 511 | C7: 広告・企業映像 | D7: 2020/12期 | E7: その後 非公開化
A8: 東北新社 | B8: 477 | C8: 広告・企業映像 | D8: 2026/3期 | E8: ①制作の比較対象
A9: HeyGen | B9: 300 | C9: AI動画・ARR | D9: $200M（1ドル150円換算） | E9: $100M→$200M を8ヶ月
A10: Synthesia | B10: 210 | C10: AI動画・ARR | D10: $140M（1ドル150円換算） | E10: ②ツールの比較対象
A11: IG Port | B11: 141 | C11: アニメ製作 | D11: 2026/5期
A12: Runway | B12: 非開示 | C12: AI動画 | D12: 非開示 | E12: 売上を公表していない
A13: Technicolor | B13: 非開示 | C13: VFX・ポスプロ | D13: 2026年 経営破綻 | E13: 上場していた制作会社は消えつつある
A14: 【当社 5期（2031年）】 | B14: ='損益計算書'!$G$12/100 | C14: ①制作＋②ツール＋③C2C | D14: 本計画
A16: ① 制作 ÷ 東北新社 | B16: ='損益計算書'!$G$4/100/477
A17: ② ツール（ARRベース）÷ Synthesia | B17: ='商品マスタ②'!$G$45/100/210

Sheet 出所と仮置き
A1: 数字の出所と、［仮置き］の一覧
A2: 投資家に聞かれて最初に困るのがここ。実測値と仮置きを混ぜないこと。★は私（Claude）が置いた値。
A3: 項目 | B3: 値 | C3: 区分 | D3: 出所・根拠
A4: ── 実測 ──
A5: 国内 映像制作市場 | B5: 4,580億円 | C5: 実測 | D5: 矢野経済研究所（BtoB映像制作）
A6: インターネット広告制作費 | B6: 4,922億円 | C6: 実測 | D6: 電通 2025年 日本の広告費（前年比104.0%）
A7: 法人数 | B7: 295万6,717社 | C7: 実測 | D7: 国税庁 令和5年度分 会社標本調査
A8: 中国 剪辑師 平均月給 | B8: 8,935元 | C8: 実測 | D8: Indeed 中国。③の価格下限の起点
A9: 中国 微短劇 直接就業者 | B9: 約69万人 | C9: 実測 | D9: 中国網絡視聴協会 2024。必要人数の母数
A10: Stripe 決済手数料 | B10: 国内カード3.6%／銀行振込1.5% | C10: 実測 | D10: stripe.com/pricing
A11: S3 Standard 東京 | B11: 1TB/月 ≈ $25 | C11: 実測 | D11: aws.amazon.com/s3/pricing
A12: CloudFront 東京 | B12: $0.085/GB | C12: 実測 | D12: 同上
A13: ベンチマーク各社の売上 | B13: 業界ベンチマーク シート | C13: 実測 | D13: 各社の決算短信・公表ARR
A14: 東証グロース 上場維持基準 | B14: 5年経過後 時価総額100億円 | C14: 実測 | D14: 日本取引所グループ
A15: ── 確認できなかった ──
A16: スキルシェア市場の映像比率 | B16: 非公表 | C16: 確認不能 | D16: ココナラ決算・矢野経済とも分離開示なし
A17: ── 松田さんの決定 ──
A18: ③ 手数料率 | B18: 一律30%（クリエイター70%） | C18: 決定 | D18: 30%から決済・送金・システム原価を引く
A19: ③ 送金・為替 | B19: 3% | C19: 決定 | D19: 中国の制作パートナー経由
A20: ③ 成約位置 | B20: 均等（価格帯の中点） | C20: 決定 | D20: 下限寄りに寄ると③は1/3になる
A21: ① クリエイター支払 | B21: 厚いまま（実効時給3,000〜6,000円） | C21: 決定 | D21: ③より高く払い優先的に押さえる
A22: ②-C セルフサーブ | B22: ②に置く／用途特化 | C22: 決定 | D22: 汎用エディタは作らない
A23: ── ★私が置いた値 ──
A24: AX倍率 | B24: 1.0 → 4.0倍 | C24: ★ | D24: 未実証。最重要前提。3倍でも営業利益率は成立する
A25: ① 商品の値引率 | B25: 一律50% | C25: ★ | D25: 企業の現行支払の半額。顧客が浮かせる額が提案の中身
A26: ① 難度係数 | B26: 3.0 / 1.8 / 1.0 / 0.8 | C26: ★ | D26: 商品構成比から平均難度を導出している
A27: ① 商品構成比 | B27: 年を追って上位帯へシフト | C27: ★ | D27: 事例が溜まるほど上の帯が取れる前提
A28: ① 営業の担当社数・リピート | B28: 40社／年6本 | C28: ★ | D28: エンタープライズ営業の標準的な水準
A29: ② SKU単価・席数・Ent比率 | B29: 商品マスタ② 参照 | C29: ★ | D29: チェックポイントに重い値付け
A30: ③ 工数・上限価格・件数 | B30: 商品マスタ③ 参照 | C30: ★ | D30: 上限は日本の支払意思。実測ではない
A31: ③ システム原価の内訳 | B31: 尺・保管期間・トークン数 | C31: ★ | D31: 単価は公表値、使用量は仮置き
A32: 希薄化係数 | B32: 資本構成の推移 参照 | C32: ★ | D32: シリーズA post 15億は未交渉
A33: ── 未確定 ──
A34: 中国の映像制作パートナー | B34: 社名 ［記入予定］ | C34: 未確定 | D34: 契約前。権利は日本側に帰属する設計
A35: パートナーの取り分 | B35: 30%側か70%側か | C35: 未確定 | D35: 契約で決まる。利益に直結する
A36: 業務委託の契約設計 | B36: ─ | C36: 未着手 | D36: 偽装請負と読まれない設計。1年目に弁護士と

Sheet 改訂履歴
A1: 改訂履歴
A2: 数字が変わった理由を残す。投資家に「前はこうだったのでは」と聞かれたときに答えられるようにするため。
A3: 版 | B3: 日付 | C3: 何を変えたか | D3: 理由・出所
A4: 0.4 | B4: 2026-09-23 | C4: B案・強気。制作を半減しツールとC2Cを伸ばす | D4: 人手に比例する①で無理をして、比例しない②③を小さく置いていたため
C5: 市場規模の次に「業界の売上」を新設 | D5: 実在企業と並べないと88億の位置が読めない
A6: 0.5 | B6: 2026-09-23 | C6: 一本値をやめ、事業×商品まで割って積み上げ | D6: 「平均単価60万」は94.5万の商売と14万の商売を1つの数字に潰していた
C7: ① 単価を「企業の現行支払×50%」に。本数は営業体制から | D7: 見積比較サイトの相場帯は中小向けに偏る。市場シェアは結果であって根拠ではない
C8: ② 5SKU・法人2階建て・②-Cセルフサーブを新設 | D8: チェックポイントと工程ツールは別売り。LoRA個別構築は②の売上
C9: ③ 14商品。下限はクリエイターの留保価格、上限は日本の支払意思 | D9: 中国 剪辑師 平均月給8,935元（Indeed中国）から時給を出して下限を逆算
A10: 0.6 | B10: 2026-09-23 | C10: ③ 工数は旧maxを標準に置き直し | D10: ミニマムの見立てが甘かった。ウェディングの下限は11,500→34,500円
C11: ③ 手数料を一律30%に。30%から決済・送金・システム原価を引く | D11: Stripe 国内カード3.6%・銀行振込1.5%／送金3%／システム原価53円/件
C12: ③ システム原価を商品別に積み上げ（120円→53円） | D12: 120円は根拠のない置き値だった。S3 3.66円/GB月・CloudFront 12.75円/GBから再計算
C13: ② ACVとARRを分離。①③のARRはゼロと明示 | D13: LoRA個別構築は一過性。Synthesia・HeyGenの公表値はARRなので土俵を揃える
C14: エンジニアを社員40名 → PM4名＋ベトナム委託19名 | D14: オフショア開発.com 2026。ベトナムBSE59.0/PG40.1のピラミッド、加重527万/年
C15: エンジニアにもAX倍率（5期2.2倍） | D15: ミドル中心なのでレビューが制約。制作の4.0倍より低く置く
C16: 中国・東欧・ロシアを委託先から外す | D16: 中国71.7・東欧104.0はベトナムより高い。ロシアは外為法の役務取引規制で対象外
C17: 中国クリエイターの登録数を採用計画（入力）に。1期30名 | D17: 工数から導出される数ではない。先に人を集めないと受注できない
C18: ③ の価格を中点から上限に | D18: 全取引が発注者の支払意思の上限で成約する前提。最も強気の置き方
C19: 管理・コーポレートを6名→3名 | D19: AX化と BPO。社外の顧問弁護士等が補う前提。その費用が4%に収まるかを検算
A20: 0.7 | B20: 2026-09-23 | C20: ③-C の件数を調整し、5期売上を120億に | D20: 個人オーダー 8,000→5,900件／企業オーダー 12,000→8,900件（比例で74%に）
C21: 版番号を繰り下げ（1.x → 0.x） | D21: 1.0 を提出版に充てるため。旧1.4→0.4／1.5→0.5／1.6→0.6
A23: ⚠ 0.4 → 0.5 は構造の作り直し、0.5 → 0.6 は前提を実勢データで詰めたもの、0.7 は③-Cの件数を落として120億に合わせたもの。5期の売上は 88.1億 → 130.3億 → 120.0億、社員は 61名 → 22名。数字が良くなった分だけ、前提の説明責任が重くなっている。
A24: ⚠ PPTX「投資家向け企画書 Ver1.4.pptx」はまだ旧番号のまま。改番するかは松田さんの指示待ち。
